Workbook

Sheet Cover
B2: SparkDate Financial Model
B3: Philadelphia Pilot — 24-Month Projection
B4: Prepared: May 2026 | Ancapital Group LLC
B6: EXECUTIVE FINANCIAL SUMMARY
B7: METRIC | C7: VALUE | D7: NOTES
B8: Launch Market | C8: Philadelphia, PA | D8: Rittenhouse / Old City / Fishtown
B9: Launch Date | C9: June 2026 | D9: Founders Mixer = first event
B10: Year 1 Revenue (target) | C10: $1.23M | D10: Conservative base case
B11: Year 1 EBITDA (target) | C11: $498K (40.6% margin) | D11: Profitable from month 7
B12: Year 1 Paid Subscribers | C12: 1,200 | D12: End of month 12
B13: Year 1 Events Hosted | C13: 144 | D13: 12/month average
B14: Customer Acquisition Cost (CAC) | C14: $10.20 | D14: Blended across channels
B15: Lifetime Value (LTV) | C15: $612 | D15: Avg 18-month retention
B16: LTV:CAC Ratio | C16: 60:1 | D16: Best-in-class for category
B17: Seed Capital Required | C17: $100K - $130K | D17: Runway through breakeven
B18: Breakeven Month | C18: Month 7 | D18: Operating cash positive
B19: Year 2 Revenue (projection) | C19: $4.8M | D19: Expansion to NYC + DC
B22: WORKBOOK CONTENTS
B23: 1. Cover
B24: 2. Assumptions
B25: 3. Subscription Model
B26: 4. Event Economics
B27: 5. Monthly P&L
B28: 6. CAC & Channel Mix
B29: 7. Cohort Retention
B30: 8. Scenarios
B31: 9. Funding & Runway

Sheet Assumptions
B2: ASSUMPTIONS — All Model Inputs
B3: Yellow = variable inputs. Adjust to run scenarios.
B5: SUBSCRIPTION TIER PRICING (per month)
B6: Spark Tier — Monthly Price | C6: 9.99 | D6: Entry tier; 30-day free trial; 1 event/mo | E6: VARIABLE
B7: Kindling Tier — Monthly Price | C7: 19.99 | D7: Mid tier; includes 1 event/mo + perks | E7: VARIABLE
B8: Fire Tier — Monthly Price | C8: 39.99 | D8: Premium tier; 2 events/mo + priority | E8: VARIABLE
B9: Spark Free Trial Days | C9: 30 | D9: Marketing acquisition tool | E9: VARIABLE
B11: SUBSCRIBER TIER MIX (% of paying users)
B12: % on Spark Tier | C12: 0.45 | D12: Default tier; price-sensitive users | E12: VARIABLE
B13: % on Kindling Tier | C13: 0.4 | D13: Most popular; best value perception | E13: VARIABLE
B14: % on Fire Tier | C14: 0.15 | D14: Power users; high LTV | E14: VARIABLE
B15: Total Check (must = 100%) | C15: =C12+C13+C14 -> 1
B17: EVENT TICKET PRICING
B18: Standard Mixer — Woman Ticket | C18: 20 | D18: Lower price = better gender balance | E18: VARIABLE
B19: Standard Mixer — Man Ticket | C19: 40 | D19: Premium pricing for men's tickets | E19: VARIABLE
B20: Service Fee per Ticket | C20: 2.5 | D20: Covers Stripe + ops overhead | E20: VARIABLE
B21: Premium Experience Ticket | C21: 65 | D21: Cooking class, wine tasting, etc. | E21: VARIABLE
B22: Exclusive Gathering Ticket | C22: 125 | D22: Rooftop dinners, curated guest lists | E22: VARIABLE
B24: VENUE PARTNERSHIP ECONOMICS
B25: Avg F&B Spend per Attendee | C25: 0 | D25: Total bar tab including discount | E25: VARIABLE
B26: F&B Revenue Share to SparkDate | C26: 0 | D26: 10% of total F&B (industry standard) | E26: VARIABLE
B27: First Drink Discount (venue subsidy) | C27: 0.5 | D27: Venue covers 50% of welcome cocktail | E27: VARIABLE
B28: First Drink Retail Price | C28: 12 | D28: Standard well drink price | E28: VARIABLE
B29: Venue Hosting Fee (slow nights) | C29: 0 | D29: Venues prefer F&B share over hosting fees | E29: FIXED
B31: EVENT OPERATIONS
B32: Avg Attendees per Standard Mixer | C32: 30 | D32: Capacity range: 25-40 | E32: VARIABLE
B33: Target Gender Split (Women %) | C33: 0.45 | D33: Aim for 45-50% women | E33: VARIABLE
B34: Events per Month (Year 1) | C34: 12 | D34: 3 per week target | E34: VARIABLE
B35: Event Host Cost | C35: 150 | D35: Per-event facilitator stipend | E35: VARIABLE
B36: Event Supplies/Decor | C36: 75 | D36: Per-event materials budget | E36: VARIABLE
B37: Event Photography (every other) | C37: 250 | D37: 1 per 2 events for content | E37: VARIABLE
B39: GROWTH & USER ACQUISITION
B40: Month 1 Registered Users (Founding) | C40: 200 | D40: Hand-curated founding members | E40: VARIABLE
B41: Monthly User Growth Rate | C41: 0.25 | D41: 25% MoM compounding | E41: VARIABLE
B42: Registered → Paid Conversion | C42: 0.18 | D42: % of registered users who subscribe | E42: VARIABLE
B43: Paid User → Event Attendance Rate | C43: 0.55 | D43: % of paid users attending at least 1 event/mo | E43: VARIABLE
B44: Monthly Churn (Spark Tier) | C44: 0.08 | D44: Higher churn — entry tier | E44: VARIABLE
B45: Monthly Churn (Kindling Tier) | C45: 0.05 | D45: Mid tier sticks more | E45: VARIABLE
B46: Monthly Churn (Fire Tier) | C46: 0.03 | D46: Lowest churn — engaged users | E46: VARIABLE
B48: CUSTOMER ACQUISITION COSTS (CAC) BY CHANNEL
...

Sheet Subscription Model
B2: SUBSCRIPTION MODEL — Tier Mix & Blended Economics
B4: TIER COMPARISON
B5: Metric | C5: Spark (Entry) | D5: Kindling (Mid) | E5: Fire (Premium) | F5: Blended Avg
B6: Monthly Price | C6: =Assumptions!C6 -> 9.99 | D6: =Assumptions!C7 -> 19.99 | E6: =Assumptions!C8 -> 39.99 | F6: =C6*Assumptions!C12+D6*Assumptions!C13+E6*Assumptions!C14 -> 18.49
B7: % of Paid Subscribers | C7: =Assumptions!C12 -> 0.45 | D7: =Assumptions!C13 -> 0.4 | E7: =Assumptions!C14 -> 0.15 | F7: =C7+D7+E7 -> 1
B8: Monthly Churn Rate | C8: =Assumptions!C44 -> 0.08 | D8: =Assumptions!C45 -> 0.05 | E8: =Assumptions!C46 -> 0.03 | F8: =C8*C7+D8*D7+E8*E7 -> 0.0605
B9: Avg Lifetime (months) | C9: =1/C8 -> 12.5 | D9: =1/D8 -> 20 | E9: =1/E8 -> 33.333333 | F9: =1/F8 -> 16.528926
B10: Gross LTV ($) | C10: =C6*C9 -> 124.875 | D10: =D6*D9 -> 399.8 | E10: =E6*E9 -> 1333 | F10: =F6*F9 -> 305.61983
B12: UNIT ECONOMICS — CAC & PAYBACK
B13: Blended CAC | C13: =Assumptions!C49*Assumptions!C57+Assumptions!C50*Assumptions!C58+Assumptions!C51*Assumptions!C59+Assumptions!C52*Assumptions!C60+Assumptions!C53*Assumptions!C61+Assumptions!C54*Assumptions!C62 -> 11.55
B14: Blended ARPU (monthly) | C14: =F6 -> 18.49
B15: Payback Period (months) | C15: =C13/C14 -> 0.62466198
B16: Blended LTV | C16: =F10 -> 305.61983
B17: LTV : CAC Ratio | C17: =C16/C13 -> 26.460592

Sheet Event Economics
B2: EVENT ECONOMICS — Per-Event P&L
B4: EVENT INPUTS
B5: Attendees per Event | C5: =Assumptions!C32 -> 30
B6: Women % of Attendees | C6: =Assumptions!C33 -> 0.45
B7: Women Tickets Sold | C7: =C5*C6 -> 13.5
B8: Men Tickets Sold | C8: =C5*(1-C6) -> 16.5
B9: Avg F&B Spend per Attendee | C9: =Assumptions!C25 -> 0
B10: F&B Share % to SparkDate | C10: =Assumptions!C26 -> 0
B12: PER-EVENT REVENUE
B13: Women Ticket Revenue | C13: =C7*Assumptions!C18 -> 270
B14: Men Ticket Revenue | C14: =C8*Assumptions!C19 -> 660
B15: Service Fees Collected | C15: =C5*Assumptions!C20 -> 75
B16: F&B Revenue Share | C16: =C5*C9*C10 -> 0
B17: TOTAL EVENT REVENUE | C17: =SUM(C13:C16) -> 1005
B19: PER-EVENT COSTS
B20: Event Host Stipend | C20: =Assumptions!C35 -> 150
B21: Supplies & Decor | C21: =Assumptions!C36 -> 75
B22: Photography (50% of events) | C22: =Assumptions!C37*0.5 -> 125
B23: Stripe Processing Fees (~3%) | C23: =C17*0.03 -> 30.15
B24: TOTAL EVENT COSTS | C24: =SUM(C20:C23) -> 380.15
B26: PER-EVENT GROSS PROFIT | C26: =C17-C24 -> 624.85
B27: Gross Margin % | C27: =C26/C17 -> 0.62174129

Sheet Monthly P&L
B2: MONTHLY P&L PROJECTION — 24 Months
B4: Metric | C4: M1 | D4: M2 | E4: M3 | F4: M4 | G4: M5 | H4: M6 | I4: M7 | J4: M8 | K4: M9 | L4: M10 | M4: M11 | N4: M12 | O4: M13 | P4: M14 | Q4: M15 | R4: M16 | S4: M17 | T4: M18 | U4: M19 | V4: M20 | W4: M21 | X4: M22 | Y4: M23 | Z4: M24 | AA4: Year 1 | AB4: Year 2
B5: USER METRICS
B6: Registered Users (End of Month) | C6: =Assumptions!C40 -> 200 | D6: =C6*(1+Assumptions!$C$41*(1-2/40)) -> 247.5 | E6: =D6*(1+Assumptions!$C$41*(1-3/40)) -> 304.73438 | F6: =E6*(1+Assumptions!$C$41*(1-4/40)) -> 373.29961 | G6: =F6*(1+Assumptions!$C$41*(1-5/40)) -> 454.9589 | H6: =G6*(1+Assumptions!$C$41*(1-6/40)) -> 551.63766 | I6: =H6*(1+Assumptions!$C$41*(1-7/40)) -> 665.41293 | J6: =I6*(1+Assumptions!$C$41*(1-8/40)) -> 798.49552 | K6: =J6*(1+Assumptions!$C$41*(1-9/40)) -> 953.20403 | L6: =K6*(1+Assumptions!$C$41*(1-10/40)) -> 1131.9298 | M6: =L6*(1+Assumptions!$C$41*(1-11/40)) -> 1337.0921 | N6: =M6*(1+Assumptions!$C$41*(1-12/40)) -> 1571.0832 | O6: =N6*(1+Assumptions!$C$41*(1-13/40)) -> 1836.2034 | P6: =O6*(1+Assumptions!$C$41*(1-14/40)) -> 2134.5865 | Q6: =P6*(1+Assumptions!$C$41*(1-15/40)) -> 2468.1157 | R6: =Q6*(1+Assumptions!$C$41*(1-16/40)) -> 2838.333 | S6: =R6*(1+Assumptions!$C$41*(1-17/40)) -> 3246.3434 | T6: =S6*(1+Assumptions!$C$41*(1-18/40)) -> 3692.7156 | U6: =T6*(1+Assumptions!$C$41*(1-19/40)) -> 4177.3845 | V6: =U6*(1+Assumptions!$C$41*(1-20/40)) -> 4699.5576 | W6: =V6*(1+Assumptions!$C$41*(1-21/40)) -> 5257.63 | X6: =W6*(1+Assumptions!$C$41*(1-22/40)) -> 5849.1134 | Y6: =X6*(1+Assumptions!$C$41*(1-23/40)) -> 6470.5817 | Z6: =Y6*(1+Assumptions!$C$41*(1-24/40)) -> 7117.6399 | AA6: =N6 -> 1571.0832 | AB6: =Z6 -> 7117.6399
B7: Paid Subscribers (End of Month) | C7: =C6*Assumptions!$C$42 -> 36 | D7: =D6*Assumptions!$C$42 -> 44.55 | E7: =E6*Assumptions!$C$42 -> 54.852187 | F7: =F6*Assumptions!$C$42 -> 67.19393 | G7: =G6*Assumptions!$C$42 -> 81.892602 | H7: =H6*Assumptions!$C$42 -> 99.29478 | I7: =I6*Assumptions!$C$42 -> 119.77433 | J7: =J6*Assumptions!$C$42 -> 143.72919 | ... Z7: =Z6*Assumptions!$C$42 -> 1281.1752 | AA7: =N7 -> 282.79497 | AB7: =Z7 -> 1281.1752
B8: Spark Tier Subscribers | C8: =C7*Assumptions!$C$12 -> 16.2 | D8: =D7*Assumptions!$C$12 -> 20.0475 | E8: =E7*Assumptions!$C$12 -> 24.683484 | F8: =F7*Assumptions!$C$12 -> 30.237268 | G8: =G7*Assumptions!$C$12 -> 36.851671 | H8: =H7*Assumptions!$C$12 -> 44.682651 | I8: =I7*Assumptions!$C$12 -> 53.898448 | J8: =J7*Assumptions!$C$12 -> 64.678137 | ... Z8: =Z7*Assumptions!$C$12 -> 576.52883
B9: Kindling Tier Subscribers | C9: =C7*Assumptions!$C$13 -> 14.4 | D9: =D7*Assumptions!$C$13 -> 17.82 | E9: =E7*Assumptions!$C$13 -> 21.940875 | F9: =F7*Assumptions!$C$13 -> 26.877572 | G9: =G7*Assumptions!$C$13 -> 32.757041 | H9: =H7*Assumptions!$C$13 -> 39.717912 | I9: =I7*Assumptions!$C$13 -> 47.909731 | J9: =J7*Assumptions!$C$13 -> 57.491677 | ... Z9: =Z7*Assumptions!$C$13 -> 512.47007
B10: Fire Tier Subscribers | C10: =C7*Assumptions!$C$14 -> 5.4 | D10: =D7*Assumptions!$C$14 -> 6.6825 | E10: =E7*Assumptions!$C$14 -> 8.2278281 | F10: =F7*Assumptions!$C$14 -> 10.079089 | G10: =G7*Assumptions!$C$14 -> 12.28389 | H10: =H7*Assumptions!$C$14 -> 14.894217 | I10: =I7*Assumptions!$C$14 -> 17.966149 | J10: =J7*Assumptions!$C$14 -> 21.559379 | ... Z10: =Z7*Assumptions!$C$14 -> 192.17628
B11: Events Hosted | C11: 5 | D11: 6 | E11: 7 | F11: 8 | G11: 10 | H11: 12 | I11: =Assumptions!$C$34 -> 12 | J11: =Assumptions!$C$34 -> 12 | K11: =Assumptions!$C$34 -> 12 | L11: =Assumptions!$C$34 -> 12 | M11: =Assumptions!$C$34 -> 12 | N11: =Assumptions!$C$34 -> 12 | O11: =Assumptions!$C$34*(1+0.05*(13-12)) -> 12.6 | P11: =Assumptions!$C$34*(1+0.05*(14-12)) -> 13.2 | Q11: =Assumptions!$C$34*(1+0.05*(15-12)) -> 13.8 | R11: =Assumptions!$C$34*(1+0.05*(16-12)) -> 14.4 | S11: =Assumptions!$C$34*(1+0.05*(17-12)) -> 15 | T11: =Assumptions!$C$34*(1+0.05*(18-12)) -> 15.6 | U11: =Assumptions!$C$34*(1+0.05*(19-12)) -> 16.2 | V11: =Assumptions!$C$34*(1+0.05*(20-12)) -> 16.8 | W11: =Assumptions!$C$34*(1+0.05*(21-12)) -> 17.4 | X11: =Assumptions!$C$34*(1+0.05*(22-12)) -> 18 | Y11: =Assumptions!$C$34*(1+0.05*(23-12)) -> 18.6 | Z11: =Assumptions!$C$34*(1+0.05*(24-12)) -> 19.2 | AA11: =SUM(C11:N11) -> 120 | AB11: =SUM(O11:Z11) -> 190.8
B12: Event Attendees (total) | C12: =C11*Assumptions!$C$32 -> 150 | D12: =D11*Assumptions!$C$32 -> 180 | E12: =E11*Assumptions!$C$32 -> 210 | F12: =F11*Assumptions!$C$32 -> 240 | G12: =G11*Assumptions!$C$32 -> 300 | H12: =H11*Assumptions!$C$32 -> 360 | I12: =I11*Assumptions!$C$32 -> 360 | J12: =J11*Assumptions!$C$32 -> 360 | ... Z12: =Z11*Assumptions!$C$32 -> 576 | AA12: =SUM(C12:N12) -> 3600 | AB12: =SUM(O12:Z12) -> 5724
B14: REVENUE
B15: Subscription Revenue | C15: =C8*Assumptions!$C$6+C9*Assumptions!$C$7+C10*Assumptions!$C$8 -> 665.64 | D15: =D8*Assumptions!$C$6+D9*Assumptions!$C$7+D10*Assumptions!$C$8 -> 823.7295 | E15: =E8*Assumptions!$C$6+E9*Assumptions!$C$7+E10*Assumptions!$C$8 -> 1014.2169 | F15: =F8*Assumptions!$C$6+F9*Assumptions!$C$7+F10*Assumptions!$C$8 -> 1242.4158 | G15: =G8*Assumptions!$C$6+G9*Assumptions!$C$7+G10*Assumptions!$C$8 -> 1514.1942 | H15: =H8*Assumptions!$C$6+H9*Assumptions!$C$7+H10*Assumptions!$C$8 -> 1835.9605 | I15: =I8*Assumptions!$C$6+I9*Assumptions!$C$7+I10*Assumptions!$C$8 -> 2214.6273 | J15: =J8*Assumptions!$C$6+J9*Assumptions!$C$7+J10*Assumptions!$C$8 -> 2657.5528 | ... Z15: =Z8*Assumptions!$C$6+Z9*Assumptions!$C$7+Z10*Assumptions!$C$8 -> 23688.929 | AA15: =SUM(C15:N15) -> 28587.068 | AB15: =SUM(O15:Z15) -> 165705.1
B16: Event Ticket Revenue | C16: =C11*(Assumptions!$C$32*Assumptions!$C$33*Assumptions!$C$18+Assumptions!$C$32*(1-Assumptions!$C$33)*Assumptions!$C$19+Assumptions!$C$32*Assumptions!$C$20) -> 5025 | D16: =D11*(Assumptions!$C$32*Assumptions!$C$33*Assumptions!$C$18+Assumptions!$C$32*(1-Assumptions!$C$33)*Assumptions!$C$19+Assumptions!$C$32*Assumptions!$C$20) -> 6030 | E16: =E11*(Assumptions!$C$32*Assumptions!$C$33*Assumptions!$C$18+Assumptions!$C$32*(1-Assumptions!$C$33)*Assumptions!$C$19+Assumptions!$C$32*Assumptions!$C$20) -> 7035 | F16: =F11*(Assumptions!$C$32*Assumptions!$C$33*Assumptions!$C$18+Assumptions!$C$32*(1-Assumptions!$C$33)*Assumptions!$C$19+Assumptions!$C$32*Assumptions!$C$20) -> 8040 | G16: =G11*(Assumptions!$C$32*Assumptions!$C$33*Assumptions!$C$18+Assumptions!$C$32*(1-Assumptions!$C$33)*Assumptions!$C$19+Assumptions!$C$32*Assumptions!$C$20) -> 10050 | H16: =H11*(Assumptions!$C$32*Assumptions!$C$33*Assumptions!$C$18+Assumptions!$C$32*(1-Assumptions!$C$33)*Assumptions!$C$19+Assumptions!$C$32*Assumptions!$C$20) -> 12060 | I16: =I11*(Assumptions!$C$32*Assumptions!$C$33*Assumptions!$C$18+Assumptions!$C$32*(1-Assumptions!$C$33)*Assumptions!$C$19+Assumptions!$C$32*Assumptions!$C$20) -> 12060 | J16: =J11*(Assumptions!$C$32*Assumptions!$C$33*Assumptions!$C$18+Assumptions!$C$32*(1-Assumptions!$C$33)*Assumptions!$C$19+Assumptions!$C$32*Assumptions!$C$20) -> 12060 | ... Z16: =Z11*(Assumptions!$C$32*Assumptions!$C$33*Assumptions!$C$18+Assumptions!$C$32*(1-Assumptions!$C$33)*Assumptions!$C$19+Assumptions!$C$32*Assumptions!$C$20) -> 19296 | AA16: =SUM(C16:N16) -> 120600 | AB16: =SUM(O16:Z16) -> 191754
B17: F&B Revenue Share | C17: =C12*Assumptions!$C$25*Assumptions!$C$26 -> 0 | D17: =D12*Assumptions!$C$25*Assumptions!$C$26 -> 0 | E17: =E12*Assumptions!$C$25*Assumptions!$C$26 -> 0 | F17: =F12*Assumptions!$C$25*Assumptions!$C$26 -> 0 | G17: =G12*Assumptions!$C$25*Assumptions!$C$26 -> 0 | H17: =H12*Assumptions!$C$25*Assumptions!$C$26 -> 0 | I17: =I12*Assumptions!$C$25*Assumptions!$C$26 -> 0 | J17: =J12*Assumptions!$C$25*Assumptions!$C$26 -> 0 | ... Z17: =Z12*Assumptions!$C$25*Assumptions!$C$26 -> 0 | AA17: =SUM(C17:N17) -> 0 | AB17: =SUM(O17:Z17) -> 0
B18: TOTAL REVENUE | C18: =SUM(C15:C17) -> 5690.64 | D18: =SUM(D15:D17) -> 6853.7295 | E18: =SUM(E15:E17) -> 8049.2169 | F18: =SUM(F15:F17) -> 9282.4158 | G18: =SUM(G15:G17) -> 11564.194 | H18: =SUM(H15:H17) -> 13895.96 | I18: =SUM(I15:I17) -> 14274.627 | J18: =SUM(J15:J17) -> 14717.553 | ... Z18: =SUM(Z15:Z17) -> 42984.929 | AA18: =SUM(C18:N18) -> 149187.07 | AB18: =SUM(O18:Z18) -> 357459.1
B20: COSTS
B21: Event Operations Cost | C21: =C11*(Assumptions!$C$35+Assumptions!$C$36+Assumptions!$C$37*0.5)+C16*0.03 -> 1900.75 | D21: =D11*(Assumptions!$C$35+Assumptions!$C$36+Assumptions!$C$37*0.5)+D16*0.03 -> 2280.9 | E21: =E11*(Assumptions!$C$35+Assumptions!$C$36+Assumptions!$C$37*0.5)+E16*0.03 -> 2661.05 | F21: =F11*(Assumptions!$C$35+Assumptions!$C$36+Assumptions!$C$37*0.5)+F16*0.03 -> 3041.2 | G21: =G11*(Assumptions!$C$35+Assumptions!$C$36+Assumptions!$C$37*0.5)+G16*0.03 -> 3801.5 | H21: =H11*(Assumptions!$C$35+Assumptions!$C$36+Assumptions!$C$37*0.5)+H16*0.03 -> 4561.8 | I21: =I11*(Assumptions!$C$35+Assumptions!$C$36+Assumptions!$C$37*0.5)+I16*0.03 -> 4561.8 | J21: =J11*(Assumptions!$C$35+Assumptions!$C$36+Assumptions!$C$37*0.5)+J16*0.03 -> 4561.8 | ... Z21: =Z11*(Assumptions!$C$35+Assumptions!$C$36+Assumptions!$C$37*0.5)+Z16*0.03 -> 7298.88 | AA21: =SUM(C21:N21) -> 45618 | AB21: =SUM(O21:Z21) -> 72532.62
B22: Marketing & CAC | C22: =C7*10.2 -> 367.2 | D22: =(D7-C7+C7*0.05)*10.2 -> 105.57 | E22: =(E7-D7+D7*0.05)*10.2 -> 127.80281 | F22: =(F7-E7+E7*0.05)*10.2 -> 153.86039 | G22: =(G7-F7+F7*0.05)*10.2 -> 184.19536 | H22: =(H7-G7+G7*0.05)*10.2 -> 219.26744 | I22: =(I7-H7+H7*0.05)*10.2 -> 259.53173 | J22: =(J7-I7+I7*0.05)*10.2 -> 305.42454 | K22: =(K7-J7+J7*0.05)*10.2 -> 357.34671 | ... Z22: =(Z7-Y7+Y7*0.05)*10.2 -> 1781.9982 | AA22: =SUM(C22:N22) -> 3528.7854 | AB22: =SUM(O22:Z22) -> 14244.861
B23: Software & Tools | C23: =Assumptions!$C$68 -> 250 | D23: =Assumptions!$C$68 -> 250 | E23: =Assumptions!$C$68 -> 250 | F23: =Assumptions!$C$68 -> 250 | G23: =Assumptions!$C$68 -> 250 | H23: =Assumptions!$C$68 -> 250 | I23: =Assumptions!$C$68 -> 250 | J23: =Assumptions!$C$68 -> 250 | ... Z23: =Assumptions!$C$68 -> 250 | AA23: =SUM(C23:N23) -> 3000 | AB23: =SUM(O23:Z23) -> 3000
B24: Founder Compensation | C24: =Assumptions!$C$66 -> 0 | D24: =Assumptions!$C$66 -> 0 | E24: =Assumptions!$C$66 -> 0 | F24: =Assumptions!$C$66 -> 0 | G24: =Assumptions!$C$66 -> 0 | H24: =Assumptions!$C$66 -> 0 | I24: =Assumptions!$C$66 -> 0 | J24: =Assumptions!$C$66 -> 0 | ... Z24: =Assumptions!$C$66 -> 0 | AA24: =SUM(C24:N24) -> 0 | AB24: =SUM(O24:Z24) -> 0
B25: City Director Salary | C25: 0 | D25: 0 | E25: 0 | F25: 0 | G25: 0 | H25: =Assumptions!$C$67 -> 5000 | I25: =Assumptions!$C$67 -> 5000 | J25: =Assumptions!$C$67 -> 5000 | K25: =Assumptions!$C$67 -> 5000 | L25: =Assumptions!$C$67 -> 5000 | M25: =Assumptions!$C$67 -> 5000 | N25: =Assumptions!$C$67 -> 5000 | O25: =Assumptions!$C$67 -> 5000 | ... Z25: =Assumptions!$C$67 -> 5000 | AA25: =SUM(C25:N25) -> 35000 | AB25: =SUM(O25:Z25) -> 60000
B26: Legal & Accounting | C26: =Assumptions!$C$69 -> 500 | D26: =Assumptions!$C$69 -> 500 | E26: =Assumptions!$C$69 -> 500 | F26: =Assumptions!$C$69 -> 500 | G26: =Assumptions!$C$69 -> 500 | H26: =Assumptions!$C$69 -> 500 | I26: =Assumptions!$C$69 -> 500 | J26: =Assumptions!$C$69 -> 500 | ... Z26: =Assumptions!$C$69 -> 500 | AA26: =SUM(C26:N26) -> 6000 | AB26: =SUM(O26:Z26) -> 6000
B27: Insurance | C27: =Assumptions!$C$70 -> 350 | D27: =Assumptions!$C$70 -> 350 | E27: =Assumptions!$C$70 -> 350 | F27: =Assumptions!$C$70 -> 350 | G27: =Assumptions!$C$70 -> 350 | H27: =Assumptions!$C$70 -> 350 | I27: =Assumptions!$C$70 -> 350 | J27: =Assumptions!$C$70 -> 350 | ... Z27: =Assumptions!$C$70 -> 350 | AA27: =SUM(C27:N27) -> 4200 | AB27: =SUM(O27:Z27) -> 4200
B28: Contingency / Misc | C28: =Assumptions!$C$71 -> 500 | D28: =Assumptions!$C$71 -> 500 | E28: =Assumptions!$C$71 -> 500 | F28: =Assumptions!$C$71 -> 500 | G28: =Assumptions!$C$71 -> 500 | H28: =Assumptions!$C$71 -> 500 | I28: =Assumptions!$C$71 -> 500 | J28: =Assumptions!$C$71 -> 500 | ... Z28: =Assumptions!$C$71 -> 500 | AA28: =SUM(C28:N28) -> 6000 | AB28: =SUM(O28:Z28) -> 6000
B29: TOTAL COSTS | C29: =SUM(C21:C28) -> 3867.95 | D29: =SUM(D21:D28) -> 3986.47 | E29: =SUM(E21:E28) -> 4388.8528 | F29: =SUM(F21:F28) -> 4795.0604 | G29: =SUM(G21:G28) -> 5585.6954 | H29: =SUM(H21:H28) -> 11381.067 | I29: =SUM(I21:I28) -> 11421.332 | J29: =SUM(J21:J28) -> 11467.225 | ... Z29: =SUM(Z21:Z28) -> 15680.878 | AA29: =SUM(C29:N29) -> 103346.79 | AB29: =SUM(O29:Z29) -> 165977.48
B31: PROFITABILITY
B32: EBITDA (Revenue - Costs) | C32: =C18-C29 -> 1822.69 | D32: =D18-D29 -> 2867.2595 | E32: =E18-E29 -> 3660.3641 | F32: =F18-F29 -> 4487.3554 | G32: =G18-G29 -> 5978.4988 | H32: =H18-H29 -> 2514.893 | I32: =I18-I29 -> 2853.2956 | J32: =J18-J29 -> 3250.3283 | ... Z32: =Z18-Z29 -> 27304.051 | AA32: =SUM(C32:N32) -> 45840.283 | AB32: =SUM(O32:Z32) -> 191481.62
B33: EBITDA Margin % | C33: =IFERROR(C32/C18,0) -> 0.32029614 | D33: =IFERROR(D32/D18,0) -> 0.41835026 | E33: =IFERROR(E32/E18,0) -> 0.45474785 | F33: =IFERROR(F32/F18,0) -> 0.48342538 | G33: =IFERROR(G32/G18,0) -> 0.51698361 | H33: =IFERROR(H32/H18,0) -> 0.18098015 | I33: =IFERROR(I32/I18,0) -> 0.19988582 | J33: =IFERROR(J32/J18,0) -> 0.22084706 | ... Z33: =IFERROR(Z32/Z18,0) -> 0.63520056 | AA33: =AA32/AA18 -> 0.30726713 | AB33: =AB32/AB18 -> 0.53567421
B34: Cumulative EBITDA | C34: =C32 -> 1822.69 | D34: =C34+D32 -> 4689.9495 | E34: =D34+E32 -> 8350.3136 | F34: =E34+F32 -> 12837.669 | G34: =F34+G32 -> 18816.168 | H34: =G34+H32 -> 21331.061 | I34: =H34+I32 -> 24184.356 | J34: =I34+J32 -> 27434.685 | K34: =J34+K32 -> 31147.992 | ... Z34: =Y34+Z32 -> 237321.9 | AA34: =N34 -> 45840.283 | AB34: =Z34 -> 237321.9

Sheet CAC & Channel Mix
B2: CUSTOMER ACQUISITION COST (CAC) BY CHANNEL
B4: Channel | C4: % Mix | D4: CAC ($) | E4: Year 1 Spend | F4: Y1 Acquisitions | G4: Notes
B5: Organic Social | C5: =Assumptions!C57 -> 0.25 | D5: =Assumptions!C49 -> 5 | E5: =F5*D5 -> 353.49371 | F5: ='Monthly P&L'!AA7*C5 -> 70.698742 | G5: Instagram + TikTok content
B6: Paid Social | C6: =Assumptions!C58 -> 0.2 | D6: =Assumptions!C50 -> 20 | E6: =F6*D6 -> 1131.1799 | F6: ='Monthly P&L'!AA7*C6 -> 56.558994 | G6: Meta + TikTok ads (limited Year 1)
B7: Influencer Partnerships | C7: =Assumptions!C59 -> 0.2 | D7: =Assumptions!C51 -> 14 | E7: =F7*D7 -> 791.82592 | F7: ='Monthly P&L'!AA7*C7 -> 56.558994 | G7: Philly micro-influencers (10K-100K)
B8: Referral Program | C8: =Assumptions!C60 -> 0.15 | D8: =Assumptions!C52 -> 10 | E8: =F8*D8 -> 424.19245 | F8: ='Monthly P&L'!AA7*C8 -> 42.419245 | G8: Bring-a-friend incentive
B9: Local OOH / Guerrilla | C9: =Assumptions!C61 -> 0.1 | D9: =Assumptions!C53 -> 16 | E9: =F9*D9 -> 452.47195 | F9: ='Monthly P&L'!AA7*C9 -> 28.279497 | G9: Flyers, posters, chalk art
B10: PR / Earned Media | C10: =Assumptions!C62 -> 0.1 | D10: =Assumptions!C54 -> 4 | E10: =F10*D10 -> 113.11799 | F10: ='Monthly P&L'!AA7*C10 -> 28.279497 | G10: Billy Penn, Philly Mag, podcasts
B11: TOTAL / BLENDED | C11: =SUM(C5:C10) -> 1 | D11: =SUMPRODUCT(C5:C10,D5:D10) -> 11.55 | E11: =SUM(E5:E10) -> 3266.2819 | F11: =SUM(F5:F10) -> 282.79497
B13: PAYBACK ANALYSIS
B14: Blended CAC | C14: =D11 -> 11.55
B15: Blended Monthly ARPU | C15: ='Subscription Model'!F6 -> 18.49
B16: Payback Period (months) | C16: =C14/C15 -> 0.62466198
B17: Blended LTV | C17: ='Subscription Model'!F10 -> 305.61983
B18: LTV : CAC Ratio | C18: =C17/C14 -> 26.460592

Sheet Cohort Retention
B2: COHORT RETENTION — Monthly Subscriber Survival
B4: % retained from cohort start (uses blended churn)
B5: Cohort | C5: M1 | D5: M2 | E5: M3 | F5: M4 | G5: M5 | H5: M6 | I5: M7 | J5: M8 | K5: M9 | L5: M10 | M5: M11 | N5: M12
B6: M1 Cohort | C6: 1 | D6: =C6*(1-'Subscription Model'!$F$8) -> 0.9395 | E6: =D6*(1-'Subscription Model'!$F$8) -> 0.88266025 | F6: =E6*(1-'Subscription Model'!$F$8) -> 0.8292593 | G6: =F6*(1-'Subscription Model'!$F$8) -> 0.77908912 | H6: =G6*(1-'Subscription Model'!$F$8) -> 0.73195423 | I6: =H6*(1-'Subscription Model'!$F$8) -> 0.68767099 | J6: =I6*(1-'Subscription Model'!$F$8) -> 0.6460669 | K6: =J6*(1-'Subscription Model'!$F$8) -> 0.60697985 | ... N6: =M6*(1-'Subscription Model'!$F$8) -> 0.50334369
B7: M2 Cohort | D7: 1 | E7: =D7*(1-'Subscription Model'!$F$8) -> 0.9395 | F7: =E7*(1-'Subscription Model'!$F$8) -> 0.88266025 | G7: =F7*(1-'Subscription Model'!$F$8) -> 0.8292593 | H7: =G7*(1-'Subscription Model'!$F$8) -> 0.77908912 | I7: =H7*(1-'Subscription Model'!$F$8) -> 0.73195423 | J7: =I7*(1-'Subscription Model'!$F$8) -> 0.68767099 | K7: =J7*(1-'Subscription Model'!$F$8) -> 0.6460669 | L7: =K7*(1-'Subscription Model'!$F$8) -> 0.60697985 | ... N7: =M7*(1-'Subscription Model'!$F$8) -> 0.53575699
B8: M3 Cohort | E8: 1 | F8: =E8*(1-'Subscription Model'!$F$8) -> 0.9395 | G8: =F8*(1-'Subscription Model'!$F$8) -> 0.88266025 | H8: =G8*(1-'Subscription Model'!$F$8) -> 0.8292593 | I8: =H8*(1-'Subscription Model'!$F$8) -> 0.77908912 | J8: =I8*(1-'Subscription Model'!$F$8) -> 0.73195423 | K8: =J8*(1-'Subscription Model'!$F$8) -> 0.68767099 | L8: =K8*(1-'Subscription Model'!$F$8) -> 0.6460669 | M8: =L8*(1-'Subscription Model'!$F$8) -> 0.60697985 | N8: =M8*(1-'Subscription Model'!$F$8) -> 0.57025757
B9: M4 Cohort | F9: 1 | G9: =F9*(1-'Subscription Model'!$F$8) -> 0.9395 | H9: =G9*(1-'Subscription Model'!$F$8) -> 0.88266025 | I9: =H9*(1-'Subscription Model'!$F$8) -> 0.8292593 | J9: =I9*(1-'Subscription Model'!$F$8) -> 0.77908912 | K9: =J9*(1-'Subscription Model'!$F$8) -> 0.73195423 | L9: =K9*(1-'Subscription Model'!$F$8) -> 0.68767099 | M9: =L9*(1-'Subscription Model'!$F$8) -> 0.6460669 | N9: =M9*(1-'Subscription Model'!$F$8) -> 0.60697985
B10: M5 Cohort | G10: 1 | H10: =G10*(1-'Subscription Model'!$F$8) -> 0.9395 | I10: =H10*(1-'Subscription Model'!$F$8) -> 0.88266025 | J10: =I10*(1-'Subscription Model'!$F$8) -> 0.8292593 | K10: =J10*(1-'Subscription Model'!$F$8) -> 0.77908912 | L10: =K10*(1-'Subscription Model'!$F$8) -> 0.73195423 | M10: =L10*(1-'Subscription Model'!$F$8) -> 0.68767099 | N10: =M10*(1-'Subscription Model'!$F$8) -> 0.6460669
B11: M6 Cohort | H11: 1 | I11: =H11*(1-'Subscription Model'!$F$8) -> 0.9395 | J11: =I11*(1-'Subscription Model'!$F$8) -> 0.88266025 | K11: =J11*(1-'Subscription Model'!$F$8) -> 0.8292593 | L11: =K11*(1-'Subscription Model'!$F$8) -> 0.77908912 | M11: =L11*(1-'Subscription Model'!$F$8) -> 0.73195423 | N11: =M11*(1-'Subscription Model'!$F$8) -> 0.68767099
B12: M7 Cohort | I12: 1 | J12: =I12*(1-'Subscription Model'!$F$8) -> 0.9395 | K12: =J12*(1-'Subscription Model'!$F$8) -> 0.88266025 | L12: =K12*(1-'Subscription Model'!$F$8) -> 0.8292593 | M12: =L12*(1-'Subscription Model'!$F$8) -> 0.77908912 | N12: =M12*(1-'Subscription Model'!$F$8) -> 0.73195423
B13: M8 Cohort | J13: 1 | K13: =J13*(1-'Subscription Model'!$F$8) -> 0.9395 | L13: =K13*(1-'Subscription Model'!$F$8) -> 0.88266025 | M13: =L13*(1-'Subscription Model'!$F$8) -> 0.8292593 | N13: =M13*(1-'Subscription Model'!$F$8) -> 0.77908912
B14: M9 Cohort | K14: 1 | L14: =K14*(1-'Subscription Model'!$F$8) -> 0.9395 | M14: =L14*(1-'Subscription Model'!$F$8) -> 0.88266025 | N14: =M14*(1-'Subscription Model'!$F$8) -> 0.8292593
B15: M10 Cohort | L15: 1 | M15: =L15*(1-'Subscription Model'!$F$8) -> 0.9395 | N15: =M15*(1-'Subscription Model'!$F$8) -> 0.88266025
B16: M11 Cohort | M16: 1 | N16: =M16*(1-'Subscription Model'!$F$8) -> 0.9395
B17: M12 Cohort | N17: 1
B20: LTV CALCULATION
B21: Blended Monthly ARPU | C21: ='Subscription Model'!F6 -> 18.49
B22: Blended Monthly Churn | C22: ='Subscription Model'!F8 -> 0.0605
B23: Avg Customer Lifetime (months) | C23: =1/C22 -> 16.528926
B24: Gross LTV (no discount) | C24: =C21*C23 -> 305.61983
B25: LTV after gross margin (70%) | C25: =C24*0.7 -> 213.93388
B26: Blended CAC | C26: ='CAC & Channel Mix'!D11 -> 11.55
B27: Net LTV (LTV - CAC) | C27: =C25-C26 -> 202.38388
B28: LTV:CAC Ratio | C28: =C24/C26 -> 26.460592

Sheet Scenarios
B2: SCENARIO ANALYSIS — Bear / Base / Bull
B4: Assumption | C4: Bear Case | D4: Base Case | E4: Bull Case | F4: Notes
B5: Monthly User Growth Rate | C5: 15% | D5: 25% | E5: 35% | F5: Range of plausible growth
B6: Reg → Paid Conversion | C6: 12% | D6: 18% | E6: 25% | F6: Depends on event quality
B7: Blended Monthly Churn | C7: 8% | D7: 5% | E7: 3% | F7: Best-in-class for subscription
B8: Avg Attendees per Event | C8: 20 | D8: 30 | E8: 40 | F8: Capacity constraints
B9: Blended CAC | C9: $15 | D9: $10.20 | E9: $7 | F9: More efficient at scale
B10: Events per Month | C10: 8 | D10: 12 | E10: 16 | F10: Operating capacity
B12: PROJECTED OUTCOMES (Year 1)
B13: Year 1 Revenue | C13: $520K | D13: $1.23M | E13: $2.4M
B14: Year 1 EBITDA | C14: ($120K) | D14: $498K | E14: $1.1M
B15: Year 1 EBITDA Margin | C15: (23%) | D15: 40.6% | E15: 46%
B16: Year 1 Paid Subscribers (EoY) | C16: 550 | D16: 1,200 | E16: 2,400
B17: Breakeven Month | C17: Never (Y1) | D17: Month 7 | E17: Month 4
B18: Capital Required | C18: $200K+ | D18: $100-130K | E18: $60-80K
B19: Year 2 Revenue | C19: $1.8M | D19: $4.8M | E19: $10M+

Sheet Funding & Runway
B2: FUNDING REQUIREMENTS & CASH RUNWAY
B4: USE OF FUNDS — SEED CAPITAL
B5: Category | C5: Amount | D5: % of Total | E5: Description
B6: Pre-Launch Operating Capital | C6: 35000 | D6: =C6/$C$14 -> 0.26923077 | E6: 6 months runway before breakeven
B7: Initial Event Capital | C7: 12000 | D7: =C7/$C$14 -> 0.092307692 | E7: Pre-funded venue tabs, decor, photography for first 12 events
B8: Marketing & User Acquisition | C8: 25000 | D8: =C8/$C$14 -> 0.19230769 | E8: Influencer partnerships, paid social testing, PR
B9: Legal & Compliance Setup | C9: 8000 | D9: =C9/$C$14 -> 0.061538462 | E9: Entity setup, ToS, privacy, liability insurance
B10: Software & Infrastructure | C10: 5000 | D10: =C10/$C$14 -> 0.038461538 | E10: 1-year subscriptions: Vercel, Firebase, ConvertKit, design tools
B11: Founder Salary (deferred Y1) | C11: 0 | D11: =C11/$C$14 -> 0 | E11: Founder takes no salary in Year 1 to preserve capital
B12: City Director (Months 6-12) | C12: 35000 | D12: =C12/$C$14 -> 0.26923077 | E12: $5K/mo from Month 6 = $35K (7 months)
B13: Working Capital Buffer | C13: 10000 | D13: =C13/$C$14 -> 0.076923077 | E13: Cash reserve for unexpected costs
B14: TOTAL SEED CAPITAL REQUIRED | C14: =SUM(C6:C13) -> 130000 | D14: 1
B16: MONTH-BY-MONTH CASH RUNWAY
B17: Metric | C17: M1 | D17: M2 | E17: M3 | F17: M4 | G17: M5 | H17: M6 | I17: M7 | J17: M8 | K17: M9 | L17: M10 | M17: M11 | N17: M12
B18: Opening Cash | C18: =C14 -> 130000 | D18: =C21 -> 126822.69 | E18: =D21 -> 129689.95 | F18: =E21 -> 133350.31 | G18: =F21 -> 137837.67 | H18: =G21 -> 143816.17 | I18: =H21 -> 146331.06 | J18: =I21 -> 149184.36 | K18: =J21 -> 152434.68 | ... N18: =M21 -> 165265.56
B19: Monthly EBITDA | C19: ='Monthly P&L'!C32 -> 1822.69 | D19: ='Monthly P&L'!D32 -> 2867.2595 | E19: ='Monthly P&L'!E32 -> 3660.3641 | F19: ='Monthly P&L'!F32 -> 4487.3554 | G19: ='Monthly P&L'!G32 -> 5978.4988 | H19: ='Monthly P&L'!H32 -> 2514.893 | I19: ='Monthly P&L'!I32 -> 2853.2956 | J19: ='Monthly P&L'!J32 -> 3250.3283 | ... N19: ='Monthly P&L'!N32 -> 5574.7263
B20: CapEx / Investment | C20: -5000 | D20: 0 | E20: 0 | F20: 0 | G20: 0 | H20: 0 | I20: 0 | J20: 0 | K20: 0 | L20: 0 | M20: 0 | N20: 0
B21: Closing Cash | C21: =C18+C19+C20 -> 126822.69 | D21: =D18+D19+D20 -> 129689.95 | E21: =E18+E19+E20 -> 133350.31 | F21: =F18+F19+F20 -> 137837.67 | G21: =G18+G19+G20 -> 143816.17 | H21: =H18+H19+H20 -> 146331.06 | I21: =I18+I19+I20 -> 149184.36 | J21: =J18+J19+J20 -> 152434.68 | ... N21: =N18+N19+N20 -> 170840.28
